Workbook

Sheet Leia-me
A1: MUTAGEN:ZERO - Armamento consolidado (v0.4)
A3: STATUS: armas, propriedades, modificacoes, componentes, municoes e escala de ruido sao CANON (Aprovacoes 001 a 012).
A4: Valores [A CALIBRAR] e os numeros de FOR minima seguem abertos, em celulas editaveis.
A6: COMO USAR
A7: 1. Aba Parametros: as cinco alavancas globais. Mexer ali repropaga por todas as abas de armas.
A8: 2. Celulas AZUIS: editaveis. PRETAS: formulas, nao edite. FUNDO AMARELO: decisao em aberto.
A9: 3. Colunas N2 e Faces2 existem para armas de DANO DUPLO (ex.: Volt-9 = 1d6 Concussao + 1d6 Eletrico).
A10: Deixe em branco para arma de dado unico. O DPR soma os dois dados automaticamente.
A11: 4. A coluna DPR desconta a propriedade Improvisada, que remove a proficiencia do ataque.
A13: A FORMULA DO DPR
A14: P(acerto) = (21 - (Defesa - bonus efetivo)) / 20, limitado entre 5% e 95%.
A15: bonus efetivo = bonus de ataque, MENOS a proficiencia se a arma for Improvisada.
... A46: Enquanto faltarem, afirmacoes sobre 'X esta forte demais' sao opiniao, nao medicao.

Sheet Parametros
A1: Parametros de referencia
A3: Parametro | B3: Valor | C3: Observacao
A4: Bonus de ataque do personagem | B4: 5 | C4: Modificador de atributo + proficiencia. Nivel baixo tipico.
A5: Modificador de dano | B5: 3 | C5: Modificador do atributo usado pela arma.
A6: Defesa do alvo | B6: 14 | C6: Zumbi comum hipotetico. [A CALIBRAR]
A7: HP do alvo | B7: 12 | C7: Zumbi comum hipotetico. [A CALIBRAR]
A8: Bonus de proficiencia | B8: 2 | C8: Descontado do ataque em armas Improvisadas. Progressao +2 a +6 [A CALIBRAR]
A10: Edite apenas a coluna B. Todas as abas de armas apontam para estas cinco celulas.

Sheet Corpo a Corpo
A1: Armas de corpo a corpo - todos os tiers
A3: Tier | B3: Arma | C3: Familia | D3: N | E3: Faces | F3: N2 | G3: Faces2 | H3: Dado | I3: Tipo de dano | J3: Ruido | K3: FOR min. | L3: Propriedades | M3: Impr. | N3: Dano medio | O3: P(acerto) | P3: DPR | Q3: F.sust. | R3: DPR sust. | S3: Rodadas | T3: Raridade
A4: TIER CIVIL
A5: Civil | B5: Punho | C5: Desarmado | D5: 1 | E5: 6 | H5: =D5&"d"&E5&IF(F5="",""," + "&F5&"d"&G5) | I5: Concussao | J5: Baixo | L5: Agil; assinatura do Pugilista | M5: - | N5: =D5*(E5+1)/2+IF(F5="",0,F5*(G5+1)/2) | O5: =MIN(0.95,MAX(0.05,(21-(Parametros!$B$6-(Parametros!$B$4-IF(M5="sim",Parametros!$B$8,0))))/20)) | P5: =O5*(N5+Parametros!$B$5)+0.05*N5 | Q5: 1 | R5: =P5*Q5 | S5: =IF(R5<=0,"",Parametros!$B$7/R5) | T5: -
A6: TIER IMPROVISO
A7: Improviso | B7: Improvisada (cano, tijolo) | C7: Contundentes | D7: 1 | E7: 4 | H7: =D7&"d"&E7&IF(F7="",""," + "&F7&"d"&G7) | I7: Concussao | J7: Baixo | L7: Improvisada | M7: sim | N7: =D7*(E7+1)/2+IF(F7="",0,F7*(G7+1)/2) | O7: =MIN(0.95,MAX(0.05,(21-(Parametros!$B$6-(Parametros!$B$4-IF(M7="sim",Parametros!$B$8,0))))/20)) | P7: =O7*(N7+Parametros!$B$5)+0.05*N7 | Q7: 1 | R7: =P7*Q7 | S7: =IF(R7<=0,"",Parametros!$B$7/R7) | T7: Abundante
A8: Improviso | B8: Martelo | C8: Contundentes | D8: 1 | E8: 4 | H8: =D8&"d"&E8&IF(F8="",""," + "&F8&"d"&G8) | I8: Concussao | J8: Baixo | L8: Improvisada, Utilitaria | M8: sim | N8: =D8*(E8+1)/2+IF(F8="",0,F8*(G8+1)/2) | O8: =MIN(0.95,MAX(0.05,(21-(Parametros!$B$6-(Parametros!$B$4-IF(M8="sim",Parametros!$B$8,0))))/20)) | P8: =O8*(N8+Parametros!$B$5)+0.05*N8 | Q8: 1 | R8: =P8*Q8 | S8: =IF(R8<=0,"",Parametros!$B$7/R8) | T8: Abundante
A9: Improviso | B9: Garrafa Quebrada | C9: Laminas Curtas | D9: 1 | E9: 4 | H9: =D9&"d"&E9&IF(F9="",""," + "&F9&"d"&G9) | I9: Cortante | J9: Silencioso | L9: Agil, Leve, Improvisada, Fragil, Arremessavel (2/4) | M9: sim | N9: =D9*(E9+1)/2+IF(F9="",0,F9*(G9+1)/2) | O9: =MIN(0.95,MAX(0.05,(21-(Parametros!$B$6-(Parametros!$B$4-IF(M9="sim",Parametros!$B$8,0))))/20)) | P9: =O9*(N9+Parametros!$B$5)+0.05*N9 | Q9: 1 | R9: =P9*Q9 | S9: =IF(R9<=0,"",Parametros!$B$7/R9) | T9: Abundante
A10: Improviso | B10: Antena de Carro | C10: Laminas Curtas | D10: 1 | E10: 4 | H10: =D10&"d"&E10&IF(F10="",""," + "&F10&"d"&G10) | I10: Cortante | J10: Silencioso | L10: Agil, Leve, Improvisada, Fragil, Alcance 2 hex | M10: sim | N10: =D10*(E10+1)/2+IF(F10="",0,F10*(G10+1)/2) | O10: =MIN(0.95,MAX(0.05,(21-(Parametros!$B$6-(Parametros!$B$4-IF(M10="sim",Parametros!$B$8,0))))/20)) | P10: =O10*(N10+Parametros!$B$5)+0.05*N10 | Q10: 1 | R10: =P10*Q10 | S10: =IF(R10<=0,"",Parametros!$B$7/R10) | T10: Abundante
A11: Improviso | B11: Corrente c/ Gancho | C11: Hastes | D11: 1 | E11: 6 | H11: =D11&"d"&E11&IF(F11="",""," + "&F11&"d"&G11) | I11: Perfurante | J11: Silencioso | L11: Duas maos, Alcance 2 hex, Improvisada, Lenta, Enganchar | M11: sim | N11: =D11*(E11+1)/2+IF(F11="",0,F11*(G11+1)/2) | O11: =MIN(0.95,MAX(0.05,(21-(Parametros!$B$6-(Parametros!$B$4-IF(M11="sim",Parametros!$B$8,0))))/20)) | P11: =O11*(N11+Parametros!$B$5)+0.05*N11 | Q11: 1 | R11: =P11*Q11 | S11: =IF(R11<=0,"",Parametros!$B$7/R11) | T11: Abundante
A12: Improviso | B12: Tampa de Bueiro | C12: Contundentes | D12: 1 | E12: 6 | H12: =D12&"d"&E12&IF(F12="",""," + "&F12&"d"&G12) | I12: Concussao | J12: Baixo | K12: 14 | L12: Duas maos, Pesada, Improvisada, Lenta; cobertura se nao atacar | M12: sim | N12: =D12*(E12+1)/2+IF(F12="",0,F12*(G12+1)/2) | O12: =MIN(0.95,MAX(0.05,(21-(Parametros!$B$6-(Parametros!$B$4-IF(M12="sim",Parametros!$B$8,0))))/20)) | P12: =O12*(N12+Parametros!$B$5)+0.05*N12 | Q12: 1 | R12: =P12*Q12 | S12: =IF(R12<=0,"",Parametros!$B$7/R12) | T12: Abundante
A13: Improviso | B13: Bateria de Carro c/ Garras | C13: Contundentes | D13: 1 | E13: 6 | H13: =D13&"d"&E13&IF(F13="",""," + "&F13&"d"&G13) | I13: Eletrico/EMP | J13: Baixo | K13: 13 | L13: Duas maos, Pesada, Improvisada, Lenta, Carga (3) | M13: sim | N13: =D13*(E13+1)/2+IF(F13="",0,F13*(G13+1)/2) | O13: =MIN(0.95,MAX(0.05,(21-(Parametros!$B$6-(Parametros!$B$4-IF(M13="sim",Parametros!$B$8,0))))/20)) | P13: =O13*(N13+Parametros!$B$5)+0.05*N13 | Q13: 1 | R13: =P13*Q13 | S13: =IF(R13<=0,"",Parametros!$B$7/R13) | T13: Abundante
A14: Improviso | B14: Lanca Artesanal | C14: Hastes | D14: 1 | E14: 8 | H14: =D14&"d"&E14&IF(F14="",""," + "&F14&"d"&G14) | I14: Perfurante | J14: Silencioso | L14: Alcance 2 hex, Fragil | M14: - | N14: =D14*(E14+1)/2+IF(F14="",0,F14*(G14+1)/2) | O14: =MIN(0.95,MAX(0.05,(21-(Parametros!$B$6-(Parametros!$B$4-IF(M14="sim",Parametros!$B$8,0))))/20)) | P14: =O14*(N14+Parametros!$B$5)+0.05*N14 | Q14: 1 | R14: =P14*Q14 | S14: =IF(R14<=0,"",Parametros!$B$7/R14) | T14: Abundante
A15: Improviso | B15: Extintor Vazio | C15: Contundentes | D15: 1 | E15: 8 | H15: =D15&"d"&E15&IF(F15="",""," + "&F15&"d"&G15) | I15: Concussao | J15: Baixo | K15: 12 | L15: Duas maos, Pesada, Improvisada, Lenta | M15: sim | N15: =D15*(E15+1)/2+IF(F15="",0,F15*(G15+1)/2) | O15: =MIN(0.95,MAX(0.05,(21-(Parametros!$B$6-(Parametros!$B$4-IF(M15="sim",Parametros!$B$8,0))))/20)) | P15: =O15*(N15+Parametros!$B$5)+0.05*N15 | Q15: 1 | R15: =P15*Q15 | S15: =IF(R15<=0,"",Parametros!$B$7/R15) | T15: Abundante
A16: TIER CIVIL
A17: Civil | B17: Cacetete | C17: Contundentes | D17: 1 | E17: 6 | H17: =D17&"d"&E17&IF(F17="",""," + "&F17&"d"&G17) | I17: Concussao | J17: Baixo | L17: - | M17: - | N17: =D17*(E17+1)/2+IF(F17="",0,F17*(G17+1)/2) | O17: =MIN(0.95,MAX(0.05,(21-(Parametros!$B$6-(Parametros!$B$4-IF(M17="sim",Parametros!$B$8,0))))/20)) | P17: =O17*(N17+Parametros!$B$5)+0.05*N17 | Q17: 1 | R17: =P17*Q17 | S17: =IF(R17<=0,"",Parametros!$B$7/R17) | T17: Comum
A18: Civil | B18: Faca / Facao | C18: Laminas Curtas | D18: 1 | E18: 6 | H18: =D18&"d"&E18&IF(F18="",""," + "&F18&"d"&G18) | I18: Cortante | J18: Silencioso | L18: Agil, Leve | M18: - | N18: =D18*(E18+1)/2+IF(F18="",0,F18*(G18+1)/2) | O18: =MIN(0.95,MAX(0.05,(21-(Parametros!$B$6-(Parametros!$B$4-IF(M18="sim",Parametros!$B$8,0))))/20)) | P18: =O18*(N18+Parametros!$B$5)+0.05*N18 | Q18: 1 | R18: =P18*Q18 | S18: =IF(R18<=0,"",Parametros!$B$7/R18) | T18: Comum
A19: Civil | B19: Machadinha | C19: Laminas Curtas | D19: 1 | E19: 6 | H19: =D19&"d"&E19&IF(F19="",""," + "&F19&"d"&G19) | I19: Cortante | J19: Silencioso | L19: Agil, Arremessavel (4/12) | M19: - | N19: =D19*(E19+1)/2+IF(F19="",0,F19*(G19+1)/2) | O19: =MIN(0.95,MAX(0.05,(21-(Parametros!$B$6-(Parametros!$B$4-IF(M19="sim",Parametros!$B$8,0))))/20)) | P19: =O19*(N19+Parametros!$B$5)+0.05*N19 | Q19: 1 | R19: =P19*Q19 | S19: =IF(R19<=0,"",Parametros!$B$7/R19) | T19: Comum
A20: Civil | B20: Taco de Golfe (Ferro 7) | C20: Contundentes | D20: 1 | E20: 6 | H20: =D20&"d"&E20&IF(F20="",""," + "&F20&"d"&G20) | I20: Concussao | J20: Baixo | L20: Agil, Leve, Fragil | M20: - | N20: =D20*(E20+1)/2+IF(F20="",0,F20*(G20+1)/2) | O20: =MIN(0.95,MAX(0.05,(21-(Parametros!$B$6-(Parametros!$B$4-IF(M20="sim",Parametros!$B$8,0))))/20)) | P20: =O20*(N20+Parametros!$B$5)+0.05*N20 | Q20: 1 | R20: =P20*Q20 | S20: =IF(R20<=0,"",Parametros!$B$7/R20) | T20: Comum
A21: Civil | B21: Tesoura de Poda de Altura | C21: Hastes | D21: 1 | E21: 6 | H21: =D21&"d"&E21&IF(F21="",""," + "&F21&"d"&G21) | I21: Cortante | J21: Silencioso | L21: Duas maos, Alcance 2 hex, Utilitaria, Fragil | M21: - | N21: =D21*(E21+1)/2+IF(F21="",0,F21*(G21+1)/2) | O21: =MIN(0.95,MAX(0.05,(21-(Parametros!$B$6-(Parametros!$B$4-IF(M21="sim",Parametros!$B$8,0))))/20)) | P21: =O21*(N21+Parametros!$B$5)+0.05*N21 | Q21: 1 | R21: =P21*Q21 | S21: =IF(R21<=0,"",Parametros!$B$7/R21) | T21: Comum
A22: Civil | B22: Macarico de Solda Portatil | C22: Dispositivos | D22: 1 | E22: 6 | H22: =D22&"d"&E22&IF(F22="",""," + "&F22&"d"&G22) | I22: Fogo | J22: Baixo | L22: Duas maos, Alcance 2 hex, Utilitaria, Carga (6) | M22: - | N22: =D22*(E22+1)/2+IF(F22="",0,F22*(G22+1)/2) | O22: =MIN(0.95,MAX(0.05,(21-(Parametros!$B$6-(Parametros!$B$4-IF(M22="sim",Parametros!$B$8,0))))/20)) | P22: =O22*(N22+Parametros!$B$5)+0.05*N22 | Q22: 1 | R22: =P22*Q22 | S22: =IF(R22<=0,"",Parametros!$B$7/R22) | T22: Comum
A23: Civil | B23: Soqueira | C23: Desarmado | D23: 2 | E23: 4 | H23: =D23&"d"&E23&IF(F23="",""," + "&F23&"d"&G23) | I23: Concussao | J23: Baixo | L23: Duas rolagens de acerto; mod. de dano SO no 1o golpe | M23: - | N23: =D23*(E23+1)/2+IF(F23="",0,F23*(G23+1)/2) | O23: =MIN(0.95,MAX(0.05,(21-(Parametros!$B$6-(Parametros!$B$4-IF(M23="sim",Parametros!$B$8,0))))/20)) | P23: =O23*(N23+Parametros!$B$5)+0.05*N23 | Q23: 1 | R23: =P23*Q23 | S23: =IF(R23<=0,"",Parametros!$B$7/R23) | T23: Comum
A24: Civil | B24: Pulverizador Costal | C24: Dispositivos | D24: 1 | E24: 4 | H24: =D24&"d"&E24&IF(F24="",""," + "&F24&"d"&G24) | I24: Quimico | J24: Baixo | L24: Duas maos, Cone (2 hex), Lenta | M24: - | N24: =D24*(E24+1)/2+IF(F24="",0,F24*(G24+1)/2) | O24: =MIN(0.95,MAX(0.05,(21-(Parametros!$B$6-(Parametros!$B$4-IF(M24="sim",Parametros!$B$8,0))))/20)) | P24: =O24*(N24+Parametros!$B$5)+0.05*N24 | Q24: 1 | R24: =P24*Q24 | S24: =IF(R24<=0,"",Parametros!$B$7/R24) | T24: Comum
A25: Civil | B25: Seringa de Pressao Veterinaria | C25: Laminas Curtas | D25: 1 | E25: 4 | H25: =D25&"d"&E25&IF(F25="",""," + "&F25&"d"&G25) | I25: Perfurante | J25: Silencioso | L25: Leve, Agil, Fragil, Recarga | M25: - | N25: =D25*(E25+1)/2+IF(F25="",0,F25*(G25+1)/2) | O25: =MIN(0.95,MAX(0.05,(21-(Parametros!$B$6-(Parametros!$B$4-IF(M25="sim",Parametros!$B$8,0))))/20)) | P25: =O25*(N25+Parametros!$B$5)+0.05*N25 | Q25: 0.5 | R25: =P25*Q25 | S25: =IF(R25<=0,"",Parametros!$B$7/R25) | T25: Comum
A26: Civil | B26: Taco de Baseball | C26: Contundentes | D26: 1 | E26: 8 | H26: =D26&"d"&E26&IF(F26="",""," + "&F26&"d"&G26) | I26: Concussao | J26: Baixo | L26: Flexivel (2 maos: 1d10) | M26: - | N26: =D26*(E26+1)/2+IF(F26="",0,F26*(G26+1)/2) | O26: =MIN(0.95,MAX(0.05,(21-(Parametros!$B$6-(Parametros!$B$4-IF(M26="sim",Parametros!$B$8,0))))/20)) | P26: =O26*(N26+Parametros!$B$5)+0.05*N26 | Q26: 1 | R26: =P26*Q26 | S26: =IF(R26<=0,"",Parametros!$B$7/R26) | T26: Comum
A27: Civil | B27: Pe de cabra | C27: Contundentes | D27: 1 | E27: 8 | H27: =D27&"d"&E27&IF(F27="",""," + "&F27&"d"&G27) | I27: Concussao | J27: Baixo | L27: Utilitaria | M27: - | N27: =D27*(E27+1)/2+IF(F27="",0,F27*(G27+1)/2) | O27: =MIN(0.95,MAX(0.05,(21-(Parametros!$B$6-(Parametros!$B$4-IF(M27="sim",Parametros!$B$8,0))))/20)) | P27: =O27*(N27+Parametros!$B$5)+0.05*N27 | Q27: 1 | R27: =P27*Q27 | S27: =IF(R27<=0,"",Parametros!$B$7/R27) | T27: Comum
A28: Civil | B28: Foice de Ceifar | C28: Laminas Longas | D28: 1 | E28: 8 | H28: =D28&"d"&E28&IF(F28="",""," + "&F28&"d"&G28) | I28: Cortante | J28: Silencioso | L28: Duas maos, Lenta, Enganchar | M28: - | N28: =D28*(E28+1)/2+IF(F28="",0,F28*(G28+1)/2) | O28: =MIN(0.95,MAX(0.05,(21-(Parametros!$B$6-(Parametros!$B$4-IF(M28="sim",Parametros!$B$8,0))))/20)) | P28: =O28*(N28+Parametros!$B$5)+0.05*N28 | Q28: 1 | R28: =P28*Q28 | S28: =IF(R28<=0,"",Parametros!$B$7/R28) | T28: Comum
A29: Civil | B29: Forcado de Feno | C29: Hastes | D29: 1 | E29: 8 | H29: =D29&"d"&E29&IF(F29="",""," + "&F29&"d"&G29) | I29: Perfurante | J29: Silencioso | L29: Duas maos, Alcance 2 hex | M29: - | N29: =D29*(E29+1)/2+IF(F29="",0,F29*(G29+1)/2) | O29: =MIN(0.95,MAX(0.05,(21-(Parametros!$B$6-(Parametros!$B$4-IF(M29="sim",Parametros!$B$8,0))))/20)) | P29: =O29*(N29+Parametros!$B$5)+0.05*N29 | Q29: 1 | R29: =P29*Q29 | S29: =IF(R29<=0,"",Parametros!$B$7/R29) | T29: Comum
A30: Civil | B30: Machado de bombeiro | C30: Laminas Longas | D30: 1 | E30: 10 | H30: =D30&"d"&E30&IF(F30="",""," + "&F30&"d"&G30) | I30: Cortante | J30: Baixo | K30: 13 | L30: Pesada, Duas maos | M30: - | N30: =D30*(E30+1)/2+IF(F30="",0,F30*(G30+1)/2) | O30: =MIN(0.95,MAX(0.05,(21-(Parametros!$B$6-(Parametros!$B$4-IF(M30="sim",Parametros!$B$8,0))))/20)) | P30: =O30*(N30+Parametros!$B$5)+0.05*N30 | Q30: 1 | R30: =P30*Q30 | S30: =IF(R30<=0,"",Parametros!$B$7/R30) | T30: Comum
A31: Civil | B31: Cilindro de Oxigenio | C31: Contundentes | D31: 1 | E31: 10 | H31: =D31&"d"&E31&IF(F31="",""," + "&F31&"d"&G31) | I31: Concussao | J31: Baixo | K31: 14 | L31: Duas maos, Pesada, Lenta, Fragil (rompe: 2d6 em area) | M31: - | N31: =D31*(E31+1)/2+IF(F31="",0,F31*(G31+1)/2) | O31: =MIN(0.95,MAX(0.05,(21-(Parametros!$B$6-(Parametros!$B$4-IF(M31="sim",Parametros!$B$8,0))))/20)) | P31: =O31*(N31+Parametros!$B$5)+0.05*N31 | Q31: 1 | R31: =P31*Q31 | S31: =IF(R31<=0,"",Parametros!$B$7/R31) | T31: Comum
A32: Civil | B32: Rebarbadora | C32: Dispositivos | D32: 1 | E32: 10 | H32: =D32&"d"&E32&IF(F32="",""," + "&F32&"d"&G32) | I32: Cortante | J32: ALTO (motor) | K32: 12 | L32: Duas maos, Pesada, Lenta, Utilitaria, Carga (4) | M32: - | N32: =D32*(E32+1)/2+IF(F32="",0,F32*(G32+1)/2) | O32: =MIN(0.95,MAX(0.05,(21-(Parametros!$B$6-(Parametros!$B$4-IF(M32="sim",Parametros!$B$8,0))))/20)) | P32: =O32*(N32+Parametros!$B$5)+0.05*N32 | Q32: 1 | R32: =P32*Q32 | S32: =IF(R32<=0,"",Parametros!$B$7/R32) | T32: Comum
A33: Civil | B33: Marreta | C33: Contundentes | D33: 1 | E33: 12 | H33: =D33&"d"&E33&IF(F33="",""," + "&F33&"d"&G33) | I33: Concussao | J33: Baixo | K33: 15 | L33: Pesada, Duas maos, Lenta | M33: - | N33: =D33*(E33+1)/2+IF(F33="",0,F33*(G33+1)/2) | O33: =MIN(0.95,MAX(0.05,(21-(Parametros!$B$6-(Parametros!$B$4-IF(M33="sim",Parametros!$B$8,0))))/20)) | P33: =O33*(N33+Parametros!$B$5)+0.05*N33 | Q33: 1 | R33: =P33*Q33 | S33: =IF(R33<=0,"",Parametros!$B$7/R33) | T33: Comum
A34: TIER MODIFICADA
A35: Modificada | B35: Cano c/ Arame Farpado | C35: Contundentes | D35: 1 | E35: 8 | H35: =D35&"d"&E35&IF(F35="",""," + "&F35&"d"&G35) | I35: Concussao | J35: Baixo | L35: Improvisada (cano 1d4 + Arame Farpado, porte Estrutural) | M35: sim | N35: =D35*(E35+1)/2+IF(F35="",0,F35*(G35+1)/2) | O35: =MIN(0.95,MAX(0.05,(21-(Parametros!$B$6-(Parametros!$B$4-IF(M35="sim",Parametros!$B$8,0))))/20)) | P35: =O35*(N35+Parametros!$B$5)+0.05*N35 | Q35: 1 | R35: =P35*Q35 | S35: =IF(R35<=0,"",Parametros!$B$7/R35) | T35: fabricada
A36: Modificada | B36: Taco c/ Pregos | C36: Contundentes | D36: 1 | E36: 10 | H36: =D36&"d"&E36&IF(F36="",""," + "&F36&"d"&G36) | I36: Concussao | J36: Baixo | L36: Flexivel (2 maos: 1d12); taco 1d8 + Pregos (Simples) | M36: - | N36: =D36*(E36+1)/2+IF(F36="",0,F36*(G36+1)/2) | O36: =MIN(0.95,MAX(0.05,(21-(Parametros!$B$6-(Parametros!$B$4-IF(M36="sim",Parametros!$B$8,0))))/20)) | P36: =O36*(N36+Parametros!$B$5)+0.05*N36 | Q36: 1 | R36: =P36*Q36 | S36: =IF(R36<=0,"",Parametros!$B$7/R36) | T36: fabricada
A37: Modificada | B37: Soqueira de Eletrodos | C37: Desarmado | D37: 2 | E37: 4 | F37: 1 | G37: 4 | H37: =D37&"d"&E37&IF(F37="",""," + "&F37&"d"&G37) | I37: Concussao + Eletrico | J37: Baixo | L37: Soqueira + Eletrodos (Simples); Carga da Celula | M37: - | N37: =D37*(E37+1)/2+IF(F37="",0,F37*(G37+1)/2) | O37: =MIN(0.95,MAX(0.05,(21-(Parametros!$B$6-(Parametros!$B$4-IF(M37="sim",Parametros!$B$8,0))))/20)) | P37: =O37*(N37+Parametros!$B$5)+0.05*N37 | Q37: 1 | R37: =P37*Q37 | S37: =IF(R37<=0,"",Parametros!$B$7/R37) | T37: fabricada
A38: TIER MILITAR
A39: Militar | B39: Katana | C39: Laminas Longas | D39: 1 | E39: 8 | H39: =D39&"d"&E39&IF(F39="",""," + "&F39&"d"&G39) | I39: Cortante | J39: Silencioso | L39: Agil, Flexivel (2 maos: 1d10) | M39: - | N39: =D39*(E39+1)/2+IF(F39="",0,F39*(G39+1)/2) | O39: =MIN(0.95,MAX(0.05,(21-(Parametros!$B$6-(Parametros!$B$4-IF(M39="sim",Parametros!$B$8,0))))/20)) | P39: =O39*(N39+Parametros!$B$5)+0.05*N39 | Q39: 1 | R39: =P39*Q39 | S39: =IF(R39<=0,"",Parametros!$B$7/R39) | T39: Raro
A40: Militar | B40: Baioneta-Adaptador M7 | C40: Laminas Curtas | D40: 1 | E40: 8 | H40: =D40&"d"&E40&IF(F40="",""," + "&F40&"d"&G40) | I40: Perfurante | J40: Silencioso | L40: Agil, Leve, Acoplada (disputa o slot com o silenciador) | M40: - | N40: =D40*(E40+1)/2+IF(F40="",0,F40*(G40+1)/2) | O40: =MIN(0.95,MAX(0.05,(21-(Parametros!$B$6-(Parametros!$B$4-IF(M40="sim",Parametros!$B$8,0))))/20)) | P40: =O40*(N40+Parametros!$B$5)+0.05*N40 | Q40: 1 | R40: =P40*Q40 | S40: =IF(R40<=0,"",Parametros!$B$7/R40) | T40: Incomum
A41: Militar | B41: Pa de Sapador | C41: Laminas Longas | D41: 1 | E41: 10 | H41: =D41&"d"&E41&IF(F41="",""," + "&F41&"d"&G41) | I41: Cortante ou Concussao | J41: conforme tipo | L41: Duas maos, Utilitaria, Dupla Face | M41: - | N41: =D41*(E41+1)/2+IF(F41="",0,F41*(G41+1)/2) | O41: =MIN(0.95,MAX(0.05,(21-(Parametros!$B$6-(Parametros!$B$4-IF(M41="sim",Parametros!$B$8,0))))/20)) | P41: =O41*(N41+Parametros!$B$5)+0.05*N41 | Q41: 1 | R41: =P41*Q41 | S41: =IF(R41<=0,"",Parametros!$B$7/R41) | T41: Incomum
...

Sheet Distancia Silenciosa
A1: Armas e dispositivos silenciosos a distancia
A3: Tier | B3: Arma | C3: Familia | D3: N | E3: Faces | F3: N2 | G3: Faces2 | H3: Dado | I3: Tipo de dano | J3: Ruido | K3: FOR min. | L3: Propriedades | M3: Impr. | N3: Dano medio | O3: P(acerto) | P3: DPR | Q3: F.sust. | R3: DPR sust. | S3: Rodadas | T3: Raridade
A4: TIER IMPROVISO
A5: Improviso | B5: Fisga de Rolamentos | C5: Projeteis Mecanicos | D5: 1 | E5: 4 | H5: =D5&"d"&E5&IF(F5="",""," + "&F5&"d"&G5) | I5: Perfurante | J5: Silencioso | L5: Leve, Duas maos, Recarga, 6/12 hex | M5: - | N5: =D5*(E5+1)/2+IF(F5="",0,F5*(G5+1)/2) | O5: =MIN(0.95,MAX(0.05,(21-(Parametros!$B$6-(Parametros!$B$4-IF(M5="sim",Parametros!$B$8,0))))/20)) | P5: =O5*(N5+Parametros!$B$5)+0.05*N5 | Q5: 0.5 | R5: =P5*Q5 | S5: =IF(R5<=0,"",Parametros!$B$7/R5) | T5: Abundante
A6: TIER CIVIL
A7: Civil | B7: Arco Artesanal | C7: Projeteis Mecanicos | D7: 1 | E7: 6 | H7: =D7&"d"&E7&IF(F7="",""," + "&F7&"d"&G7) | I7: Perfurante | J7: Silencioso | L7: 16/48 hex, municao recuperavel | M7: - | N7: =D7*(E7+1)/2+IF(F7="",0,F7*(G7+1)/2) | O7: =MIN(0.95,MAX(0.05,(21-(Parametros!$B$6-(Parametros!$B$4-IF(M7="sim",Parametros!$B$8,0))))/20)) | P7: =O7*(N7+Parametros!$B$5)+0.05*N7 | Q7: 1 | R7: =P7*Q7 | S7: =IF(R7<=0,"",Parametros!$B$7/R7) | T7: Comum
A8: Civil | B8: Dardo de Atletismo | C8: Hastes | D8: 1 | E8: 6 | H8: =D8&"d"&E8&IF(F8="",""," + "&F8&"d"&G8) | I8: Perfurante | J8: Silencioso | L8: Alcance 2 hex empunhado, Arremessavel (6/12) | M8: - | N8: =D8*(E8+1)/2+IF(F8="",0,F8*(G8+1)/2) | O8: =MIN(0.95,MAX(0.05,(21-(Parametros!$B$6-(Parametros!$B$4-IF(M8="sim",Parametros!$B$8,0))))/20)) | P8: =O8*(N8+Parametros!$B$5)+0.05*N8 | Q8: 1 | R8: =P8*Q8 | S8: =IF(R8<=0,"",Parametros!$B$7/R8) | T8: Comum
A9: Civil | B9: Besta de Caca | C9: Projeteis Mecanicos | D9: 1 | E9: 8 | H9: =D9&"d"&E9&IF(F9="",""," + "&F9&"d"&G9) | I9: Perfurante | J9: Silencioso | L9: Duas maos, Recarga, 10/20 hex | M9: - | N9: =D9*(E9+1)/2+IF(F9="",0,F9*(G9+1)/2) | O9: =MIN(0.95,MAX(0.05,(21-(Parametros!$B$6-(Parametros!$B$4-IF(M9="sim",Parametros!$B$8,0))))/20)) | P9: =O9*(N9+Parametros!$B$5)+0.05*N9 | Q9: 0.5 | R9: =P9*Q9 | S9: =IF(R9<=0,"",Parametros!$B$7/R9) | T9: Incomum
A10: Civil | B10: Arpao Pneumatico de Pesca | C10: Projeteis Mecanicos | D10: 1 | E10: 8 | H10: =D10&"d"&E10&IF(F10="",""," + "&F10&"d"&G10) | I10: Perfurante | J10: Baixo (pneumatico) | L10: Duas maos, Recarga, 5/10 hex, projetil por cabo | M10: - | N10: =D10*(E10+1)/2+IF(F10="",0,F10*(G10+1)/2) | O10: =MIN(0.95,MAX(0.05,(21-(Parametros!$B$6-(Parametros!$B$4-IF(M10="sim",Parametros!$B$8,0))))/20)) | P10: =O10*(N10+Parametros!$B$5)+0.05*N10 | Q10: 0.5 | R10: =P10*Q10 | S10: =IF(R10<=0,"",Parametros!$B$7/R10) | T10: Incomum
A11: TIER MILITAR
A12: Militar | B12: Besta Pesada | C12: Projeteis Mecanicos | D12: 1 | E12: 10 | H12: =D12&"d"&E12&IF(F12="",""," + "&F12&"d"&G12) | I12: Perfurante | J12: Silencioso | L12: Duas maos, Recarga, 20/60 hex, municao recuperavel | M12: - | N12: =D12*(E12+1)/2+IF(F12="",0,F12*(G12+1)/2) | O12: =MIN(0.95,MAX(0.05,(21-(Parametros!$B$6-(Parametros!$B$4-IF(M12="sim",Parametros!$B$8,0))))/20)) | P12: =O12*(N12+Parametros!$B$5)+0.05*N12 | Q12: 0.5 | R12: =P12*Q12 | S12: =IF(R12<=0,"",Parametros!$B$7/R12) | T12: Raro
A13: Militar | B13: Lancador de Cabo de Abordagem | C13: Projeteis Mecanicos | D13: 1 | E13: 6 | H13: =D13&"d"&E13&IF(F13="",""," + "&F13&"d"&G13) | I13: Perfurante | J13: Baixo (pneumatico) | L13: Duas maos, Recarga, 8/16 hex; cabo sustenta uma pessoa | M13: - | N13: =D13*(E13+1)/2+IF(F13="",0,F13*(G13+1)/2) | O13: =MIN(0.95,MAX(0.05,(21-(Parametros!$B$6-(Parametros!$B$4-IF(M13="sim",Parametros!$B$8,0))))/20)) | P13: =O13*(N13+Parametros!$B$5)+0.05*N13 | Q13: 0.5 | R13: =P13*Q13 | S13: =IF(R13<=0,"",Parametros!$B$7/R13) | T13: Incomum
A14: TIER PROTOTIPO
A15: Prototipo | B15: 'Cantor' dardo chamariz | C15: Projeteis Mecanicos | D15: 1 | E15: 6 | H15: =D15&"d"&E15&IF(F15="",""," + "&F15&"d"&G15) | I15: Perfurante | J15: Silencioso | L15: Carga (2) por cena, 12 hex; cria ruido Nivel 2 em OUTRO hex | M15: - | N15: =D15*(E15+1)/2+IF(F15="",0,F15*(G15+1)/2) | O15: =MIN(0.95,MAX(0.05,(21-(Parametros!$B$6-(Parametros!$B$4-IF(M15="sim",Parametros!$B$8,0))))/20)) | P15: =O15*(N15+Parametros!$B$5)+0.05*N15 | Q15: 1 | R15: =P15*Q15 | S15: =IF(R15<=0,"",Parametros!$B$7/R15) | T15: Epico
A17: F.sust. = fracao dos turnos em que a arma consegue atacar. 0,5 = Recarga custa 1 Acao, disparo em turnos alternados.
A18: CORRIGIDO na v0.4: Fisga de Rolamentos e Seringa de Pressao tinham Recarga mas estavam com F.sust. = 1, inflando o DPR.
A19: O 'CANTOR' ESTA AQUI, e nao em Armas de Fogo: e um lancador de dardos, nao uma arma de polvora.
A20: Seu Ruido Silencioso esta CORRETO pela regra canonica (tensao mecanica = Silencioso) e NAO e excecao a regra da Vigilia.
A21: BESTA PESADA era so 'Besta' no canon original; renomeada na Aprovacao 010 para conviver com a Besta de Caca.

Sheet Armas de Fogo
A1: Armas de fogo
A3: Tier | B3: Arma | C3: Familia | D3: N | E3: Faces | F3: N2 | G3: Faces2 | H3: Dado | I3: Ruido | J3: Alc. normal | K3: Alc. longo | L3: Pente | M3: Modos | N3: Silenciavel | O3: Municao | P3: Dano medio | Q3: P(acerto) | R3: DPR | S3: Tiros/alvo | T3: Raridade
A4: TIER CIVIL
A5: Civil | B5: Pistola leve | C5: Pistolas | D5: 1 | E5: 6 | H5: =D5&"d"&E5&IF(F5="",""," + "&F5&"d"&G5) | I5: Medio | J5: 12 | K5: 36 | L5: 12 | M5: Unico | N5: Sim | O5: Leve | P5: =D5*(E5+1)/2+IF(F5="",0,F5*(G5+1)/2) | Q5: =MIN(0.95,MAX(0.05,(21-(Parametros!$B$6-Parametros!$B$4))/20)) | R5: =Q5*(P5+Parametros!$B$5)+0.05*P5 | S5: =IF(OR(Q5<=0,R5<=0),"",(Parametros!$B$7/R5)/Q5) | T5: Comum
A6: Civil | B6: SMG | C6: Longas | D6: 1 | E6: 6 | H6: =D6&"d"&E6&IF(F6="",""," + "&F6&"d"&G6) | I6: Medio | J6: 8 | K6: 24 | L6: 30 | M6: Unico | N6: Sim | O6: Leve | P6: =D6*(E6+1)/2+IF(F6="",0,F6*(G6+1)/2) | Q6: =MIN(0.95,MAX(0.05,(21-(Parametros!$B$6-Parametros!$B$4))/20)) | R6: =Q6*(P6+Parametros!$B$5)+0.05*P6 | S6: =IF(OR(Q6<=0,R6<=0),"",(Parametros!$B$7/R6)/Q6) | T6: Incomum
A7: Civil | B7: Pistola pesada | C7: Pistolas | D7: 1 | E7: 8 | H7: =D7&"d"&E7&IF(F7="",""," + "&F7&"d"&G7) | I7: Medio | J7: 10 | K7: 30 | L7: 8 | M7: Unico | N7: Sim | O7: Pesado | P7: =D7*(E7+1)/2+IF(F7="",0,F7*(G7+1)/2) | Q7: =MIN(0.95,MAX(0.05,(21-(Parametros!$B$6-Parametros!$B$4))/20)) | R7: =Q7*(P7+Parametros!$B$5)+0.05*P7 | S7: =IF(OR(Q7<=0,R7<=0),"",(Parametros!$B$7/R7)/Q7) | T7: Incomum
A8: Civil | B8: Carabina | C8: Longas | D8: 1 | E8: 8 | H8: =D8&"d"&E8&IF(F8="",""," + "&F8&"d"&G8) | I8: Alto | J8: 20 | K8: 60 | L8: 20 | M8: Unico, Rajada | N8: Sim | O8: Rifle | P8: =D8*(E8+1)/2+IF(F8="",0,F8*(G8+1)/2) | Q8: =MIN(0.95,MAX(0.05,(21-(Parametros!$B$6-Parametros!$B$4))/20)) | R8: =Q8*(P8+Parametros!$B$5)+0.05*P8 | S8: =IF(OR(Q8<=0,R8<=0),"",(Parametros!$B$7/R8)/Q8) | T8: Incomum
A9: Civil | B9: Revolver | C9: Pistolas | D9: 1 | E9: 10 | H9: =D9&"d"&E9&IF(F9="",""," + "&F9&"d"&G9) | I9: Alto | J9: 8 | K9: 24 | L9: 6 | M9: Unico | N9: NAO | O9: Pesado | P9: =D9*(E9+1)/2+IF(F9="",0,F9*(G9+1)/2) | Q9: =MIN(0.95,MAX(0.05,(21-(Parametros!$B$6-Parametros!$B$4))/20)) | R9: =Q9*(P9+Parametros!$B$5)+0.05*P9 | S9: =IF(OR(Q9<=0,R9<=0),"",(Parametros!$B$7/R9)/Q9) | T9: Comum
A10: Civil | B10: Rifle de caca | C10: Longas | D10: 1 | E10: 10 | H10: =D10&"d"&E10&IF(F10="",""," + "&F10&"d"&G10) | I10: Alto | J10: 24 | K10: 72 | L10: 5 | M10: Unico | N10: Sim | O10: Rifle | P10: =D10*(E10+1)/2+IF(F10="",0,F10*(G10+1)/2) | Q10: =MIN(0.95,MAX(0.05,(21-(Parametros!$B$6-Parametros!$B$4))/20)) | R10: =Q10*(P10+Parametros!$B$5)+0.05*P10 | S10: =IF(OR(Q10<=0,R10<=0),"",(Parametros!$B$7/R10)/Q10) | T10: Incomum
A11: Civil | B11: Rifle de precisao | C11: Longas | D11: 1 | E11: 12 | H11: =D11&"d"&E11&IF(F11="",""," + "&F11&"d"&G11) | I11: Alto | J11: 40 | K11: 120 | L11: 5 | M11: Unico | N11: Sim | O11: Rifle | P11: =D11*(E11+1)/2+IF(F11="",0,F11*(G11+1)/2) | Q11: =MIN(0.95,MAX(0.05,(21-(Parametros!$B$6-Parametros!$B$4))/20)) | R11: =Q11*(P11+Parametros!$B$5)+0.05*P11 | S11: =IF(OR(Q11<=0,R11<=0),"",(Parametros!$B$7/R11)/Q11) | T11: Raro
A12: Civil | B12: Espingarda | C12: Espingardas | D12: 2 | E12: 6 | H12: =D12&"d"&E12&IF(F12="",""," + "&F12&"d"&G12) | I12: Alto | J12: 4 | K12: 12 | L12: 6 | M12: Unico | N12: NAO | O12: Cartucho | P12: =D12*(E12+1)/2+IF(F12="",0,F12*(G12+1)/2) | Q12: =MIN(0.95,MAX(0.05,(21-(Parametros!$B$6-Parametros!$B$4))/20)) | R12: =Q12*(P12+Parametros!$B$5)+0.05*P12 | S12: =IF(OR(Q12<=0,R12<=0),"",(Parametros!$B$7/R12)/Q12) | T12: Incomum
A13: TIER MILITAR
A14: Militar | B14: Metralhadora | C14: Longas | D14: 1 | E14: 8 | H14: =D14&"d"&E14&IF(F14="",""," + "&F14&"d"&G14) | I14: Alto | J14: 24 | K14: 72 | L14: 50 | M14: Automatico (habil. de Classe) | N14: NAO | O14: Rifle | P14: =D14*(E14+1)/2+IF(F14="",0,F14*(G14+1)/2) | Q14: =MIN(0.95,MAX(0.05,(21-(Parametros!$B$6-Parametros!$B$4))/20)) | R14: =Q14*(P14+Parametros!$B$5)+0.05*P14 | S14: =IF(OR(Q14<=0,R14<=0),"",(Parametros!$B$7/R14)/Q14) | T14: Raro
A15: Militar | B15: Carabina M-24 'Regua' | C15: Longas | D15: 1 | E15: 10 | H15: =D15&"d"&E15&IF(F15="",""," + "&F15&"d"&G15) | I15: Alto | J15: 24 | K15: 72 | L15: 20 | M15: Unico, Rajada | N15: Sim | O15: Rifle | P15: =D15*(E15+1)/2+IF(F15="",0,F15*(G15+1)/2) | Q15: =MIN(0.95,MAX(0.05,(21-(Parametros!$B$6-Parametros!$B$4))/20)) | R15: =Q15*(P15+Parametros!$B$5)+0.05*P15 | S15: =IF(OR(Q15<=0,R15<=0),"",(Parametros!$B$7/R15)/Q15) | T15: Incomum
A16: Militar | B16: SMG M-11 'Costura' | C16: Longas | D16: 1 | E16: 6 | H16: =D16&"d"&E16&IF(F16="",""," + "&F16&"d"&G16) | I16: Medio | J16: 10 | K16: 30 | L16: 32 | M16: Unico, Rajada (-1) | N16: Sim | O16: Leve | P16: =D16*(E16+1)/2+IF(F16="",0,F16*(G16+1)/2) | Q16: =MIN(0.95,MAX(0.05,(21-(Parametros!$B$6-Parametros!$B$4))/20)) | R16: =Q16*(P16+Parametros!$B$5)+0.05*P16 | S16: =IF(OR(Q16<=0,R16<=0),"",(Parametros!$B$7/R16)/Q16) | T16: Incomum
A17: Militar | B17: Espingarda 'Portaria' | C17: Espingardas | D17: 1 | E17: 10 | H17: =D17&"d"&E17&IF(F17="",""," + "&F17&"d"&G17) | I17: Alto | J17: 6 | K17: 18 | L17: 8 | M17: Unico, Espalhamento (2 hex) | N17: NAO | O17: Cartucho | P17: =D17*(E17+1)/2+IF(F17="",0,F17*(G17+1)/2) | Q17: =MIN(0.95,MAX(0.05,(21-(Parametros!$B$6-Parametros!$B$4))/20)) | R17: =Q17*(P17+Parametros!$B$5)+0.05*P17 | S17: =IF(OR(Q17<=0,R17<=0),"",(Parametros!$B$7/R17)/Q17) | T17: Incomum
A18: TIER CORPORATIVA
A19: Corporativa | B19: Pistola 'Fiador' | C19: Pistolas | D19: 1 | E19: 10 | H19: =D19&"d"&E19&IF(F19="",""," + "&F19&"d"&G19) | I19: Medio | J19: 12 | K19: 36 | L19: 10 | M19: Unico; DRM + Telemetria | N19: Sim | O19: Pesado | P19: =D19*(E19+1)/2+IF(F19="",0,F19*(G19+1)/2) | Q19: =MIN(0.95,MAX(0.05,(21-(Parametros!$B$6-Parametros!$B$4))/20)) | R19: =Q19*(P19+Parametros!$B$5)+0.05*P19 | S19: =IF(OR(Q19<=0,R19<=0),"",(Parametros!$B$7/R19)/Q19) | T19: Raro
A20: Corporativa | B20: Fuzil 'Testemunha' | C20: Longas | D20: 1 | E20: 10 | H20: =D20&"d"&E20&IF(F20="",""," + "&F20&"d"&G20) | I20: Alto | J20: 30 | K20: 90 | L20: 10 | M20: Unico; Marcacao | N20: Sim | O20: Rifle | P20: =D20*(E20+1)/2+IF(F20="",0,F20*(G20+1)/2) | Q20: =MIN(0.95,MAX(0.05,(21-(Parametros!$B$6-Parametros!$B$4))/20)) | R20: =Q20*(P20+Parametros!$B$5)+0.05*P20 | S20: =IF(OR(Q20<=0,R20<=0),"",(Parametros!$B$7/R20)/Q20) | T20: Epico
A21: Corporativa | B21: Lanca-agulhas 'Costureira' | C21: Longas | D21: 1 | E21: 6 | F21: 1 | G21: 6 | H21: =D21&"d"&E21&IF(F21="",""," + "&F21&"d"&G21) | I21: Baixo | J21: 12 | K21: 36 | L21: 12 | M21: Unico; Envenenado | N21: Sim | O21: Exotica | P21: =D21*(E21+1)/2+IF(F21="",0,F21*(G21+1)/2) | Q21: =MIN(0.95,MAX(0.05,(21-(Parametros!$B$6-Parametros!$B$4))/20)) | R21: =Q21*(P21+Parametros!$B$5)+0.05*P21 | S21: =IF(OR(Q21<=0,R21<=0),"",(Parametros!$B$7/R21)/Q21) | T21: Raro
A22: Corporativa | B22: Espingarda 'Cordao' | C22: Espingardas | D22: 1 | E22: 8 | H22: =D22&"d"&E22&IF(F22="",""," + "&F22&"d"&G22) | I22: Alto | J22: 6 | K22: 18 | L22: 6 | M22: Unico; cartucho de contencao | N22: NAO | O22: Cartucho | P22: =D22*(E22+1)/2+IF(F22="",0,F22*(G22+1)/2) | Q22: =MIN(0.95,MAX(0.05,(21-(Parametros!$B$6-Parametros!$B$4))/20)) | R22: =Q22*(P22+Parametros!$B$5)+0.05*P22 | S22: =IF(OR(Q22<=0,R22<=0),"",(Parametros!$B$7/R22)/Q22) | T22: Raro
A23: Corporativa | B23: Emissor EMP 'Apagao' | C23: Dispositivos | D23: 1 | E23: 8 | H23: =D23&"d"&E23&IF(F23="",""," + "&F23&"d"&G23) | I23: Baixo | J23: 3 | K23: 3 | L23: 3 | M23: Cone 3 hex; Carga (3) | N23: n/a | O23: Carga | P23: =D23*(E23+1)/2+IF(F23="",0,F23*(G23+1)/2) | Q23: =MIN(0.95,MAX(0.05,(21-(Parametros!$B$6-Parametros!$B$4))/20)) | R23: =Q23*(P23+Parametros!$B$5)+0.05*P23 | S23: =IF(OR(Q23<=0,R23<=0),"",(Parametros!$B$7/R23)/Q23) | T23: Raro
A24: TIER PROTOTIPO
A25: Prototipo | B25: 'Vigilia' eletromagnetico | C25: Longas | D25: 1 | E25: 10 | H25: =D25&"d"&E25&IF(F25="",""," + "&F25&"d"&G25) | I25: Baixo | J25: 24 | K25: 72 | L25: 0 | M25: Unico; Trilha de Calor (5) | N25: n/a | O25: Sucata ferrosa | P25: =D25*(E25+1)/2+IF(F25="",0,F25*(G25+1)/2) | Q25: =MIN(0.95,MAX(0.05,(21-(Parametros!$B$6-Parametros!$B$4))/20)) | R25: =Q25*(P25+Parametros!$B$5)+0.05*P25 | S25: =IF(OR(Q25<=0,R25<=0),"",(Parametros!$B$7/R25)/Q25) | T25: Epico
A26: Prototipo | B26: 'Ariete' antimaterial 20mm | C26: Longas | D26: 1 | E26: 12 | H26: =D26&"d"&E26&IF(F26="",""," + "&F26&"d"&G26) | I26: Alto | J26: 40 | K26: 120 | L26: 1 | M26: Unico, Lenta, Linha | N26: NAO | O26: Exotica | P26: =D26*(E26+1)/2+IF(F26="",0,F26*(G26+1)/2) | Q26: =MIN(0.95,MAX(0.05,(21-(Parametros!$B$6-Parametros!$B$4))/20)) | R26: =Q26*(P26+Parametros!$B$5)+0.05*P26 | S26: =IF(OR(Q26<=0,R26<=0),"",(Parametros!$B$7/R26)/Q26) | T26: Epico
A28: Tiros/alvo = consumo esperado de municao por alvo. E a metrica que importa para a economia, nao o DPR.
A29: RAJADA e restrita a armas de calibre RIFLE (Aprovacao 009): DPR 7,28, excecao NOMEADA ao teto de 6,025.
A30: Em Rajada o critico soma UM dado adicional em vez de dobrar - pico cai de 43 para 33 sem mexer na media.
A31: ESPINGARDA 2d6 da 6,35, tambem excecao NOMEADA: o preco e o alcance de 4/12 hex, ou seja 6 metros.
A32: Revolver, espingardas e metralhadora NAO aceitam silenciador. No revolver, por razao fisica: o vao entre
A33: tambor e cano vaza gas e som.
A34: 'Vigilia' teve o Ruido Silencioso NEGADO pelo Diretor e ficou em Baixo - arma de fogo nunca silencia.
A35: O 'Cantor' NAO esta nesta aba: e lancador de dardos, nao arma de polvora. Ver Distancia Silenciosa.

Sheet Municoes Especiais
A1: Municao - Municoes Especiais (renomeadas de Cargas Especiais, Aprovacao 018)
A3: Carga | B3: Efeito | C3: Sistema que toca | D3: Observacao
A4: Subsonica | B4: -1 nivel de Ruido e -1 DEGRAU NO DADO | C4: Ruido / Horda | D4: O -1 no dado protege a 'Vigilia': silencio se paga em dano.
A5: Perfurante (AP) | B5: Transfixante (2): reduz o bonus de cobertura do alvo | C5: Cobertura | D5: Depende da tabela de resistencias [A CALIBRAR].
A6: Expansiva | B6: +1 degrau no dado; -2 no ataque contra alvo com armadura | C6: Dano | D6: Depende da tabela de resistencias [A CALIBRAR].
A7: Incendiaria | B7: +1d4 Fogo; acende o hexagono do alvo | C7: Fogo / Infeccao | D7: Cria terreno, como a 'Boca de Forno'.
A8: Envenenada | B8: Aplica Envenenado; so contra alvo organico | C8: Condicoes | D8: So Projeteis e Exotica: veneno e coisa de arqueiro.
A9: Explosiva | B9: Dano no hexagono e metade nos adjacentes | C9: Area | D9: A unica area disponivel fora de habilidade de Classe.
A10: Tracante | B10: +1 no ataque; o alvo e seus aliados sabem de onde veio o tiro | C10: Tatica | D10: Ganho de precisao pago em exposicao, nao em recurso.
A11: Contencao | B11: Sem dano; alvo testa FOR ou fica Atordoado | C11: Captura / Investigacao | D11: Exclusividade da espingarda. Porta de entrada para capturar vivo.
A12: Cauterizante | B12: Mutante abatido por ela NAO gera pontos de Infeccao | C12: Infeccao | D12: RARIDADE EXTREMA. 5o item anti-Infeccao e o mais perigoso: municao replica mais facil que arma unica.
A13: Sobrecarga (EMP) | B13: +1d4 Eletrico contra alvo com cibernetica | C13: Cibernetica | D13: Sinergia com o cenario cyberpunk.
A15: PRINCIPIO: identico ao das armas de tier alto - o poder vem de EFEITO, nunca de numero. Nenhuma carga e '+2 de dano'.
A16: MUNICAO PADRAO e o que se saqueia, sem modificador. MUNICOES ESPECIAIS NAO SE ACHAM: SE FABRICAM,
A17: com os mesmos oito componentes das Modificacoes e nas mesmas duas vias, Gambiarra e Oficina.
A18: REGRA DE CUSTO, simetrica as Modificacoes: municao de GAMBIARRA soma +1 a FAIXA DE TRAVAMENTO enquanto carregada.
A19: Municao suja emporcalha a arma. Municao de Oficina nao tem penalidade.
A20: PISO DE RUIDO: qualquer empilhamento de reducoes (silenciador + subsonica, por exemplo) para no minimo em BAIXO.
A21: ARMA DE FOGO NUNCA CHEGA A SILENCIOSO, por mais que se empilhe. Ex.: rifle Alto -> silenciador -> Medio -> subsonica -> Baixo.
A22: LOTE: fabricar produz um LOTE de N unidades [A CALIBRAR], nunca uma bala unica - sem isso a mesa trava em contabilidade.
A23: FLECHAS RECUPERAVEIS PERDEM A MELHORIA: recupera-se o PROJETIL, nao a carga. Flecha envenenada recuperada volta comum.

Sheet Compatibilidade
A1: Matriz de compatibilidade - Carga Especial x Pool de municao
A3: Carga | B3: Leve | C3: Pesado | D3: Rifle | E3: Cartucho | F3: Projeteis | G3: Exotica
A4: Subsonica | B4: SIM | C4: SIM | D4: SIM | E4: - | F4: - | G4: SIM
A5: Perfurante (AP) | B5: - | C5: SIM | D5: SIM | E5: - | F5: SIM | G5: SIM
A6: Expansiva | B6: SIM | C6: SIM | D6: - | E6: SIM | F6: - | G6: -
A7: Incendiaria | B7: - | C7: - | D7: SIM | E7: SIM | F7: SIM | G7: -
A8: Envenenada | B8: - | C8: - | D8: - | E8: - | F8: SIM | G8: SIM
A9: Explosiva | B9: - | C9: - | D9: - | E9: SIM | F9: SIM | G9: SIM
A10: Tracante | B10: SIM | C10: - | D10: SIM | E10: - | F10: - | G10: -
A11: Contencao | B11: - | C11: - | D11: - | E11: SIM | F11: - | G11: -
A12: Cauterizante | B12: - | C12: - | D12: SIM | E12: SIM | F12: SIM | G12: -
A13: Sobrecarga (EMP) | B13: - | C13: SIM | D13: SIM | E13: - | F13: - | G13: SIM
A15: O que a matriz produz sem nenhuma regra extra:
A16: VENENO E COISA DE ARQUEIRO - Envenenada so existe em Projeteis e Exotica.
A17: CONTENCAO E EXCLUSIVIDADE DA ESPINGARDA - unico pool com o cartucho de volume necessario.
A18: O RIFLE E O UNICO que combina Perfurante, Tracante e Subsonica, o que o torna a arma do atirador
A19: tatico e nao apenas a de maior alcance.

Sheet Propriedades
A1: Propriedades de arma
A3: Propriedade | B3: Efeito mecanico | C3: Origem
A4: Agil | B4: Pode usar AGI no lugar de FOR no ataque e no dano. | C4: Aprov. 006
A5: Leve | B5: Ocupa meio slot de inventario. | C5: Aprov. 006
A6: Pesada | B6: Exige FOR minima (12 a 16, por arma). Abaixo dela, desvantagem no ataque. | C6: Aprov. 009
A7: Duas maos | B7: Ocupa as duas maos. Sem escudo nem item na outra. | C7: Aprov. 006
A8: Lenta | B8: Apos atacar, perde a Reacao ate o inicio do proximo turno. | C8: Aprov. 006
A9: Improvisada | B9: Nao soma o bonus de proficiencia ao ataque. | C9: Aprov. 006
A10: Utilitaria | B10: Serve como ferramenta: vantagem em testes de FOR para arrombar. | C10: Aprov. 006
A11: Arremessavel (X/Y) | B11: Arremessavel a X/Y hexagonos, usando o mesmo atributo do corpo a corpo. | C11: Aprov. 006
A12: Alcance 2 hex | B12: Ataca a ate 2 hexagonos, SEM ficar adjacente ao alvo. | C12: Aprov. 006
A13: Fragil | B13: Em um 1 natural, a arma quebra. | C13: Aprov. 006
A14: Flexivel | B14: Uma ou duas maos. Com duas maos sobe UM degrau na escada de dados (teto 1d12). | C14: Aprov. 007
... A27: Linha | B27: Ao acertar, a mesma rolagem se aplica a uma segunda criatura no hexagono imediatamente atras. | C27: Aprov. 009
A29: NAO EXISTE a propriedade 'Confiavel' (nunca trava): rejeitada na Aprovacao 009 e substituida por faixa reduzida
A30: a 1 natural confirmado, para nao criar um recurso de turno morto nem pressionar a reabertura da Acao Bonus.
A31: ATENCAO A TERMINOLOGIA: 'Pesada' aqui e PROPRIEDADE DE ARMA (exige FOR). O PORTE de modificacao ofensiva
A32: chama-se SIMPLES e ESTRUTURAL (Aprovacao 012) - antes eram 'Leve' e 'Pesada', o que colidia com esta tabela.

Sheet Modificacoes
A1: Sistema de Modificacoes - Gambiarra e Oficina
A3: Familia | B3: Modificacao | C3: Porte | D3: Slots | E3: Efeito | F3: Gambiarra (campo) | G3: Oficina (Refugio) | H3: CD INT
A4: OFENSIVA
A5: Ofensiva | B5: Pregos / Parafusos | C5: Simples | D5: 1 | E5: +1 degrau de dado | F5: Sucata x2 | G5: Sucata x1, Pecas x1 | H5: 10
A6: Ofensiva | B6: Cabeca Lastrada | C6: Simples | D6: 1 | E6: +1 degrau; a arma ganha Lenta | F6: Sucata x2, Pecas x1 | G6: Pecas x2, Liga x1 | H6: 12
A7: Ofensiva | B7: Laminas Soldadas | C7: Simples | D7: 1 | E7: +1 degrau; dano passa a Cortante (e o Ruido a Silencioso) | F7: Sucata x2, Pecas x1 | G7: Liga x1, Pecas x1 | H7: 14
A8: Ofensiva | B8: Arame Farpado | C8: ESTRUTURAL | D8: 2 | E8: +2 degraus de dado | F8: Sucata x3, Pecas x1 | G8: Sucata x2, Liga x1 | H8: 12
A9: Ofensiva | B9: Ponta Incendiaria | C9: Simples | D9: 1 | E9: +1d4 Fogo; consome 1 Quimica por combate | F9: Quimica x2, Fiacao x1 | G9: Quimica x2, Pecas x1 | H9: 15
A10: Ofensiva | B10: Eletrodos | C10: Simples | D10: 1 | E10: +1d4 Eletrico; gasta carga da Celula | F10: Fiacao x2, Eletronicos x1, Celula x1 | G10: Eletronicos x1, Celula x1, Liga x1 | H10: 16
A11: PRECISAO
A12: Precisao | B12: Mira Telescopica | C12: - | D12: 1 | E12: +50% no alcance normal | F12: Optica x2, Pecas x1 | G12: Optica x1, Liga x1 | H12: 14
A13: Precisao | B13: Designador Laser | C13: - | D13: 1 | E13: +1 no ataque a distancia | F13: Optica x1, Eletronicos x1, Celula x1 | G13: Eletronicos x1, Celula x1 | H13: 16
A14: Precisao | B14: Coronha Estabilizada | C14: - | D14: 1 | E14: Remove a desvantagem no alcance longo | F14: Sucata x2, Pecas x2 | G14: Pecas x2, Liga x1 | H14: 12
A15: FURTIVA
A16: Furtiva | B16: Silenciador | C16: - | D16: 1 | E16: -1 nivel de Ruido, por 30 disparos | F16: Pecas x2, Quimica x1 | G16: Liga x1, Pecas x1, Quimica x1 | H16: 15
A17: Furtiva | B17: Pano Abafador | C17: - | D17: 1 | E17: -1 nivel de Ruido, SO em corpo a corpo de concussao | F17: Sucata x1 | G17: - (nao existe) | H17: 8
A18: CONFIABILIDADE
A19: Confiabilidade | B19: Recalibragem | C19: - | D19: 1 | E19: +1 degrau de conservacao | F19: Pecas x2, Quimica x1 | G19: Pecas x1, Quimica x1 | H19: 12
A20: Confiabilidade | B20: Pecas Novas | C20: - | D20: 1 | E20: +1 degrau de conservacao e imune a queda por 1 sessao | F20: - (so Oficina) | G20: Liga x1, Pecas x2 | H20: 15
A21: Confiabilidade | B21: Guarda de Ejecao | C21: - | D21: 1 | E21: Reduz em 1 a faixa de travamento | F21: Pecas x2 | G21: Pecas x1, Liga x1 | H21: 14
A22: SUPORTE
A23: Suporte | B23: Guarda-mao | C23: - | D23: 1 | E23: +1 de Defesa em corpo a corpo; nao perde a arma se desarmado | F23: Sucata x2, Pecas x1 | G23: Liga x1, Pecas x1 | H23: 10
A24: Suporte | B24: Lanterna Acoplada | C24: - | D24: 1 | E24: Ilumina 4 hex a frente | F24: Fiacao x1, Celula x1 | G24: Eletronicos x1, Celula x1 | H24: 10
A25: Suporte | B25: Alca Tatica | C25: - | D25: 1 | E25: Trocar de arma deixa de custar a interacao livre | F25: Sucata x1 | G25: Sucata x1, Pecas x1 | H25: 8
A27: SLOTS (Aprovacao 013): modificacao ofensiva Simples = 1 slot, Estrutural = 2 slots, e QUALQUER
A28: modificacao NAO OFENSIVA = 1 slot, salvo indicacao contraria. Antes da 013 as onze nao-ofensivas
A29: nao declaravam custo em slot nenhum, o que tornava impossivel fechar qualquer build.
A30: FAMILIA RENOMEADA na Aprovacao 013: 'Utilitaria' virou SUPORTE, porque Utilitaria ja era uma
A31: PROPRIEDADE de arma (vantagem em testes de FOR para arrombar). Era a terceira colisao de nome do sistema.
A32: QUEBRA e TRAVAMENTO sao contadores DISTINTOS que NUNCA se somam (Aprovacao 013): quebra e a arma se
A33: partir (Fragil e o +1 da Gambiarra); travamento e a arma emperrar (1 natural em arma de fogo).
A34: Por isso a Guarda de Ejecao NAO se anula: ela reduz o travamento, a Gambiarra piora a quebra.
A35: ELETRODOS e PONTA INCENDIARIA em arma de multiplas rolagens: o dado extra entra UMA VEZ SO (Aprovacao 013).
A36: Soqueira + Eletrodos = 2d4 Concussao + 1d4 Eletrico, nao +2d4.
A37: PORTES RENOMEADOS na Aprovacao 012: SIMPLES (+1 degrau, 1 slot) e ESTRUTURAL (+2 degraus, 2 slots).
A38: Antes chamavam-se 'Leve' e 'Pesada', o que colidia com as PROPRIEDADES de arma de mesmo nome. Sao coisas distintas:
... A47: A soqueira de raios se fabrica aqui: Soqueira + Eletrodos = 2d4 Concussao + 1d4 Eletrico.

Sheet Componentes
A1: Os oito componentes
A3: Componente | B3: Escassez | C3: O que e | D3: Nota de economia
A4: Sucata | B4: Abundante | C4: Metal torto, madeira, entulho, lata | D4: Base de quase toda gambiarra. A palavra FICA no componente (Aprovacao 018).
A5: Pecas Mecanicas | B5: Comum | C5: Molas, parafusos, engrenagens, canos, roscas | D5: O mais versatil das cinco familias.
A6: Fiacao | B6: Comum | C6: Cabo, fio de cobre, isolamento | D6: Porta de entrada das modificacoes eletricas.
A7: Quimica | B7: Incomum | C7: Solvente, adesivo, propelente, acido | D7: Consumida por uso na Ponta Incendiaria, nas cargas e no SORO DE CAMPO do Medico (Aprov. 023).
A8: Optica | B8: Incomum | C8: Lente, vidro tratado, visor | D8: Gargalo das modificacoes de Precisao.
A9: Eletronicos | B9: Incomum | C9: Placa, sensor, chip | D9: Nao se fabrica: so se desmonta de algo que ja existia.
A10: Celula de Energia | B10: Incomum | C10: Bateria que ainda segura carga | D10: Disputa com o gerador do Refugio.
A11: Liga Pre-Queda | B11: RARO | C11: Aco e titanio de qualidade militar | D11: O GARGALO PROPOSITAL: separa Gambiarra de Oficina. Nao se fabrica.
A13: A lista e curta de proposito: componente demais vira contabilidade em vez de decisao.
A14: Os mesmos oito componentes fabricam MODIFICACOES e CARGAS ESPECIAIS de municao.
A15: A Liga Pre-Queda e o que puxa o grupo para fora do Refugio - a unica forma de ter Oficina de verdade e saquear.
A17: REGRA GERAL DE PRODUCAO (Aprovacao 023): TUDO QUE SE FABRICA CONSOME COMPONENTE.
A18: Vale fora das Modificacoes - Soro de Campo do Medico (Quimica), municao artesanal, e qualquer receita futura.
A19: Por que e regra e nao caso a caso: 'um por descanso longo' sem custo de material e producao INFINITA,
A20: porque o descanso e renovavel e o componente nao. O componente transforma a frequencia em TETO, nao piso.
A21: Para implementadores: nenhuma receita pode ter lista de componentes vazia. Sem custo declarado = [A CALIBRAR],
A22: nunca 'de graca'. As QUANTIDADES por receita continuam [A CALIBRAR]; a regra fixa que existe custo, nao quanto.
A24: APROVACAO 023 tambem separou os DOIS SOROS, que ate entao dividiam o mesmo nome:
A25: Soro Anti-Infeccao = raridade extrema, ZERA a Trilha inteira, trava de distribuicao do Diretor.
A26: Soro de Campo = Medico nivel 14, um por descanso longo, custa Quimica, remove N pontos e NUNCA zera.
... A30: e com isso a palavra OFICINA desceu de 3 para 2 sentidos - a primeira colisao resolvida por renomeacao.

Sheet Bestiario
A1: Bestiario MUTAGEN:ZERO - 18 criaturas (Aprovacao 025) + 20 novas, Bloco 5 (Aprovacao 035)
A2: Regua canonica: Zumbi comum Defesa 14 / HP 12. Parametros do personagem: ataque +5, dano +3, Defesa 13, arma 1d8.
A4: Criatura | B4: ND | C4: Custo | D4: HP | E4: Defesa | F4: Ataque | G4: Dano | H4: Tipo de dano | I4: Mov (hex) | J4: Tamanho | K4: Gera Infec. | L4: Uiva | M4: Vulneravel | N4: Resistente | O4: MUITO Resist. | P4: IMUNE | Q4: Habilidade
A5: Zumbi | B5: 0 | C5: 1 | D5: 12 | E5: 14 | F5: +4 | G5: 1d6 | H5: Necrotico | I5: 4 | J5: Medio | K5: SIM | L5: - | M5: Fogo | N5: Perfurante, Balistico | Q5: A REGUA. Anda 4 hex contra 6 do personagem: recuar e sempre opcao.
A6: Cachorro Zumbi | B6: 0 | C6: 1 | D6: 8 | E6: 15 | F6: +5 | G6: 1d4 | H6: Necrotico | I6: 8 | J6: Miudo | K6: SIM | L6: - | M6: Fogo | Q6: Matilha: Vantagem se um aliado esta adjacente ao mesmo alvo.
A7: Zumbi Resistente | B7: 1 | C7: 2 | D7: 14 | E7: 16 | F7: +4 | G7: 1d6 | H7: Necrotico | I7: 4 | J7: Medio | K7: SIM | L7: - | M7: CONCUSSAO | O7: Perfurante, Balistico | Q7: Placas sao blindagem, nao carne: quase nao ganhou HP. Da sujeito ao grau Muito Resistente.
A8: Zumbi Cibernetico | B8: 1 | C8: 1.5 | D8: 14 | E8: 15 | F8: +5 | G8: 1d6 | H8: Necrotico | I8: 5 | J8: Medio | K8: SIM | L8: - | M8: Eletrico/EMP | N8: Perfurante, Necrotico, Quimico | Q8: Usa cobertura: ataque a distancia contra ele rola com Desvantagem. Empurra o grupo para o corpo a corpo.
A9: Maratonista | B9: 1 | C9: 1 | D9: 10 | E9: 15 | F9: +5 | G9: 1d6 | H9: Necrotico | I9: 10 | J9: Medio | K9: SIM | L9: - | M9: Fogo | Q9: Investida: fecha do alcance de rifle ate o corpo a corpo em um turno. Anula o alcance.
A10: Arrastador | B10: 1 | C10: 1 | D10: 10 | E10: 13 | F10: +5 | G10: 1d6 | H10: Necrotico | I10: 3 | J10: Miudo | K10: SIM | L10: - | M10: Fogo | N10: Perfurante, Balistico | Q10: Emboscada: comeca Escondido, Percepcao CD 14 para achar, 1o ataque com Vantagem. Tornozelo: AGI CD 13 ou Agarrado.
A11: Vigia | B11: 1 | C11: 0 | D11: 12 | E11: 15 | F11: - | G11: - | H11: - | I11: 8 | J11: Medio | K11: NAO | L11: - | M11: Fogo | Q11: NAO ATACA. Alarme: foge para a borda; se sair do mapa o Medidor de Horda sobe +10.
A12: Saqueador Humano | B12: 1 | C12: 0.5 | D12: 16 | E12: 14 | F12: +5 | G12: 1d6 | H12: Balistico | I12: 6 | J12: Medio | K12: NAO | L12: - | N12: o que a armadura der | Q12: Usa o CATALOGO DE ARMAS inteiro (e o Ruido delas). Negociavel: Persuasao ou Intimidacao CD 15 encerra o combate.
A13: Mutante | B13: 2 | C13: 6.5 | D13: 28 | E13: 15 | F13: +7 | G13: 1d8+2 | H13: Necrotico | I13: 5 | J13: Medio | K13: SIM | L13: - | M13: FOGO | N13: Perfurante, Necrotico | Q13: Regeneracao: cura 5 HP no inicio do turno, ANULADA se sofreu Fogo desde o turno anterior.
A14: Uivante | B14: 2 | C14: 3 | D14: 20 | E14: 14 | F14: +5 | G14: 1d6 | H14: Necrotico | I14: 4 | J14: Medio | K14: SIM | L14: SIM | M14: Fogo | Q14: Uivo: gasta a Acao, Ruido ALTO (3), gera Atracao em raio amplo. A TESE DO JOGO: nenhuma resposta e gratis.
A15: Cachorro Explosivo | B15: 2 | C15: 0.5 | D15: 8 | E15: 15 | F15: - | G15: 3d6 | H15: Fogo+Concussao | I15: 10 | J15: Miudo | K15: NAO | L15: aprox. ALTA | M15: Fogo (e um presente) | Q15: NAO ATACA: detona ao chegar adjacente. Raio 2 hex, AGI CD 14 para metade. Matar com fogo a distancia = detona longe.
A16: Touro Mecanico | B16: 2 | C16: 3.5 | D16: 35 | E16: 15 | F16: +7 | G16: 2d8 | H16: Concussao | I16: 6 | J16: GRANDE | K16: NAO | L16: - | M16: Eletrico/EMP | N16: Perfurante, Balistico | Q16: Investida: 6+ hex reto, alvo testa FOR CD 15 ou e empurrado 3 hex e fica Caido. PRIMEIRA criatura Grande: destrava o Extrator.
A17: Casulo | B17: 2 | C17: 8 | D17: 25 | E17: 10 | F17: - | G17: - | H17: - | I17: 0 | J17: GRANDE | K17: NAO | L17: - | M17: FOGO | N17: Perfurante, Balistico | Q17: IMOVEL, nao ataca. Gestacao: gera 1 Zumbi (ND 0) ao fim de cada rodada. Um cronometro com HP.
A18: Zumbi de Sangue | B18: 3 | C18: 18 | D18: 30 | E18: 14 | F18: +6 | G18: 1d6 | H18: Necrotico | I18: 4 | J18: Medio | K18: SIM | L18: - | M18: Fogo | Q18: Explosao ao morrer: 2 hex, AGI CD 14, falha = 2d6 Necrotico +2 Infeccao. ZUMBIS NO RAIO CURAM 2d6. Anti-corpo-a-corpo.
A19: Doutora Zumbi | B19: 3 | C19: 5 | D19: 24 | E19: 14 | F19: +6 | G19: 1d6 | H19: Necrotico | I19: 5 | J19: Medio | K19: SIM | L19: - | M19: Fogo | N19: Perfurante | Q19: Tratamento: gasta a Acao para curar 2d6 num zumbi/mutante adjacente. Alvo prioritario no 2, depois do Uivante.
A20: Zumbi Venenoso | B20: 4 | C20: 30 | D20: 45 | E20: 15 | F20: +10 | G20: 1d8+2 | H20: Necrotico | I20: 4 | J20: Medio | K20: SIM | L20: - | M20: FOGO | N20: Perfurante, Balistico | P20: QUIMICO | Q20: AURA (2 hex): quem COMECA o turno dentro sofre 1d6 Quimico e testa CON CD 14 ou ganha 1 Infeccao. UNICA imune a dano no MVP.
A21: Cuspidor | B21: 4 | C21: 3.5 | D21: 35 | E21: 14 | F21: +10 | G21: 2d6 | H21: Quimico | I21: 3 | J21: Medio | K21: NAO | L21: - | M21: Fogo | N21: Quimico (NAO imune) | Q21: Ataca a 8 HEX. Cuspe corrosivo ignora meia cobertura. Produz acido mas nao E feito dele: por isso Resistente, nao Imune.
A22: Gigante Mutagenico | B22: 5 | C22: 132 | D22: 80 | E22: 16 | F22: +11 | G22: 2d8+4 | H22: Necrotico | I22: 5 | J22: ENORME | K22: SIM | L22: - | M22: FOGO | N22: Perfurante, Balistico, Concussao | P22: Agarrado, Enganchar (condicao, por tamanho) | Q22: DUAS ACOES. Miasma (1 hex): 1 Infeccao por turno, sem teste. CISAO: a 0 HP vira 4 Zumbis. A luta tem dois atos.
A23: Rastejante | B23: 0 | C23: 1 | D23: 10 | E23: 12 | F23: +4 | G23: 1d6 | H23: Necrotico | I23: 2 | J23: Miudo | K23: SIM | L23: NAO | M23: Fogo | N23: Perfurante, Balistico | Q23: Emboscada Rasteira: Escondido sob cobertura baixa, Percepcao CD14, 1o ataque com Vantagem. Versao ND0 do Arrastador, sem Tornozelo e so 2 hex de movimento.
A24: Zumbi Inchado | B24: 1 | C24: 2 | D24: 14 | E24: 14 | F24: +5 | G24: 1d6 | H24: Necrotico | I24: 4 | J24: Medio | K24: SIM | L24: NAO | M24: Fogo | Q24: Nuvem de Gas ao morrer: raio 1 hex, CON CD13, falha = 2d4 Quimico (sucesso = metade). NAO gera Infeccao pela explosao, so pela mordida.
A25: Enxame de Ratos Mutantes | B25: 1 | C25: 0.5 | D25: 10 | E25: 12 | F25: +5 (Vantagem) | G25: 1d6 | H25: Perfurante | I25: 6 | J25: Miudo | K25: NAO | L25: NAO | M25: Concussao | Q25: Enxame: ataca sempre com Vantagem. Mordida Perfurante por natureza - RESOLVE a pendencia de fonte de Perfurante fora do controle do Mestre (GDD_Equipamentos S11).
A26: Zumbi Guia | B26: 1 | C26: 1 | D26: 12 | E26: 15 | F26: - | G26: - | H26: - | I26: 8 | J26: Medio | K26: NAO | L26: NAO | M26: Fogo | Q26: NAO ATACA. Direcao (raio 4 hex): zumbis no raio ganham Vantagem no proximo ataque. Par silencioso do Uivante - cobra em Infeccao, nao em Horda. Medido acompanhado (nao dobra, S4.3).
A27: Fungo Ambulante | B27: 2 | C27: 7 | D27: 22 | E27: 13 | F27: +5 | G27: 1d6+1 | H27: Quimico | I27: 3 | J27: Medio | K27: SIM | L27: NAO | M27: Fogo | N27: Quimico | Q27: Nuvem de Esporos (1 hex): CON CD12, falha = 1d4 Quimico + 1 Infeccao. Aura COM TESTE (diferente do Miasma do Gigante, que e sem teste - CD mais baixa pois e 3 ND mais fraco).
A28: Zumbi Viscoso | B28: 2 | C28: 2.5 | D28: 26 | E28: 13 | F28: +5 | G28: 1d4+1 | H28: Necrotico | I28: 3 | J28: Medio | K28: SIM | L28: NAO | M28: Fogo | N28: Perfurante, Balistico | Q28: Lodo Pegajoso: ao acertar, AGI CD13 ou deslocamento reduzido a metade at o fim do proximo turno do alvo. Controle de posicao, nao dano - 1d4 e o menor dado do catalogo.
A29: Zumbi Corrosivo | B29: 3 | C29: 5 | D29: 30 | E29: 13 | F29: +6 | G29: 1d6+2 | H29: Necrotico | I29: 4 | J29: Medio | K29: SIM | L29: NAO | M29: Fogo | N29: Quimico | Q29: Aura Corrosiva (1 hex): CON CD13, falha = 1d6 de local (GDD_Equipamentos S3) desce 1 estado de desgaste. Primeira criatura a atacar EQUIPAMENTO direto - RESOLVE quebra-armadura alem do Touro.
A30: Posto Automatizado | B30: 3 | C30: 4 | D30: 32 | E30: 15 | F30: +9 | G30: 2d6 | H30: Balistico | I30: 0 | J30: Medio | K30: NAO | L30: NAO | M30: Eletrico/EMP | N30: Perfurante | Q30: Sensor de Movimento: Vantagem contra quem se moveu no turno. Hackear (Mecanica ou Eletronica CD15, Vantagem com Kit de Eletronica): fica Inerte e pode ser OPERADO por um personagem depois.
A31: Carcaca de Aco | B31: 3 | C31: 7 | D31: 32 | E31: 18 | F31: +8 | G31: 1d6+1 | H31: Necrotico | I31: 2 | J31: Medio | K31: SIM | L31: NAO | M31: Concussao | N31: Perfurante, Balistico | Q31: Defesa mais alta do catalogo (18, acima do proprio Gigante) e sem nenhuma habilidade - paga tudo em Defesa, cobra em rodadas: Movimento 2 hex, nunca alcanca quem recua.
A32: Parasita de Controle | B32: 3 | C32: 4 | D32: 20 | E32: 14 | F32: +8 (10 hex) | G32: 1d4 | H32: Perfurante | I32: 7 | J32: Miudo | K32: NAO | L32: NAO | M32: Fogo | Q32: Controle parasitario: se o alvo tem HP <= metade do maximo, CON CD14 ou fica Controlado e ataca o aliado mais proximo. Quase inofensivo vs grupo saudavel; letal sem descanso entre cenas.
A33: Mutante Encouracado | B33: 4 | C33: 9 | D33: 50 | E33: 15 | F33: +10 | G33: 1d10+3 | H33: Perfurante | I33: 4 | J33: Medio | K33: NAO | L33: NAO | M33: Concussao | N33: Perfurante | Q33: Espinhos Rasgantes (Rasgar variante): todo acerto, AGI CD14 ou desce 1 estado de desgaste - sem limite por combate, mas TESTAVEL (o Touro e automatico, 1x/combate). NAO gera Infeccao (dano Perfurante, nao Necrotico).
A34: Colmeia Ambulante | B34: 6 | C34: 120 | D34: 95 | E34: 15 | F34: +13 | G34: 2d6+3 | H34: Necrotico | I34: 4 | J34: Grande | K34: SIM | L34: NAO | M34: Fogo | N34: Perfurante, Balistico | Q34: Zumbido Constante (2 hex, CON CD15, falha=1 Infeccao): aura TESTAVEL, nao automatica como o Miasma do Gigante. Cisao: a 0 HP libera 3 Insetos Mutantes (ND0).
A35: Devorador de Aco | B35: 6 | C35: 70 | D35: 110 | E35: 16 | F35: +9 (reduzido) | G35: 2d8+3 | H35: Concussao | I35: 5 | J35: Grande | K35: NAO | L35: NAO | M35: Eletrico/EMP | N35: Perfurante, Balistico | Q35: Mandibulas Trituradoras: todo acerto desce 1 estado de desgaste, SEM LIMITE por combate. Ataque reduzido de proposito (ND6 pleno seria +13) para nao destruir equipamento rapido demais - pedido do Diretor.
A36: Enxame de Morcegos Mutantes | B36: 6 | C36: 100 | D36: 80 | E36: 17 | F36: +13 | G36: 2d6+2 | H36: Perfurante | I36: 8 | J36: Medio | K36: NAO | L36: NAO | M36: Concussao | Q36: Voo Erratico: ataque corpo a corpo comum contra ele tem Desvantagem (so a arma de alcance/distancia funciona bem). Mordida Perfurante real, fora do controle do Mestre.
A37: Sentinela Corporativa | B37: 6-7 | C37: 230 | D37: 100 | E37: 20 | F37: +14 | G37: 2d8+4 | H37: Balistico | I37: 5 | J37: Medio | K37: NAO | L37: NAO | M37: Eletrico/EMP | N37: Perfurante, Balistico | Q37: DUAS ACOES. Nunca recarrega nem trava. Critico com 19-20 natural (em vez de Rasgar) - a resposta ao personagem Furtivo de Defesa alta, nao ao tanque. Primeira criatura que NAO e morto-vivo nem mutante.
A38: Enxame-Rainha | B38: 8 | C38: 260 | D38: 125 | E38: 18 | F38: +16 | G38: 2d6+3 | H38: Necrotico | I38: 6 | J38: Grande | K38: SIM | L38: NAO | M38: Fogo | N38: Perfurante | Q38: Secrecao da Prole (2 hex, CON CD16): 1d6 Necrotico + 1 Infeccao se falhar. Grito de Comando (6 hex): zumbis/mutantes curam 5 HP e Vantagem. Chamado Constante: Medidor de Horda +5/rodada so por ela existir.
A39: Matriarca Mutagenica | B39: 8 | C39: 255 | D39: 130 | E39: 18 | F39: +16 | G39: 2d8+4 | H39: Necrotico | I39: 5 | J39: Grande | K39: SIM | L39: NAO | M39: Fogo | N39: Perfurante, Necrotico | Q39: Oviposicao (processo paralelo, nao custa a Acao): gera Zumbis direto (nao Casulo) at 4 vivos gerados por ela. Regeneracao 3 HP/turno, anulada por Fogo. Versao movel do Casulo.
A40: Colosso de Sucata | B40: 9 | C40: 350 | D40: 170 | E40: 18 | F40: +17 | G40: 2d10+5 | H40: Concussao | I40: 6 | J40: ENORME | K40: NAO | L40: NAO | M40: Eletrico/EMP | N40: Perfurante, Balistico | Q40: DUAS ACOES. Rasgar 3x/combate (o triplo do Touro). Investida como o Touro (FOR CD17). Nuvem de Estilhacos (1 hex, fim do turno): 1d8 Concussao. Colapso em Sucata: a 0 HP vira 2 Drones de Sucata (ND2).
A41: Nucleo Mutagenico | B41: 10 | C41: 720 | D41: 160 | E41: 19 | F41: +19 | G41: 2d10+6 | H41: Necrotico | I41: 5 | J41: ENORME | K41: SIM | L41: NAO | M41: Fogo | N41: Perfurante, Balistico, Concussao | P41: Agarrado, Enganchar | Q41: DUAS ACOES. Miasma (2 hex, sem teste, 1 Infeccao - dobro do raio do Gigante). Pulso de Mutagenese (4 hex, a cada 2 rodadas): +1 Infeccao extra em quem ja tem. Cisao: a 0 HP vira 6 Zumbis. O chefe desenhado para esgotar a Trilha, nao o HP.
...

Sheet Consumiveis
A1: Consumiveis - reposicao e saque (Aprovacao 028)
A2: Principio: NADA SE GASTA SEM TER UMA VIA DE VOLTA DECLARADA. Espelho da regra de producao da Aprovacao 023.
A4: 1. CARGA (N) - a unificacao
A5: Item | B5: Cargas | C5: Tipo de carga | D5: Componente que repoe | E5: Escassez | F5: Nota
A6: Soqueira "Volt-9" | B6: 6 | C6: Eletrica | D6: Celula de Energia | E6: Incomum | F6: DPR 6,35 carregada x 4,08 vazia. Encher custa 6 Celulas: e decisao de Refugio, nao rotina.
A7: "Ferro de Marca" | B7: 10 | C7: Incendiaria | D7: Quimica | E7: Incomum | F7: RARIDADE EXTREMA. Cauterizar zera Infeccao de um ataque. O item mais caro de manter do jogo.
A8: Emissor EMP "Apagao" | B8: 3 | C8: Eletrica | D8: Celula de Energia | E8: Incomum | F8: Cone 3 hex. NAO distingue amigo de inimigo.
A9: Tonfa de Choque Antimotim | B9: 4 | C9: Eletrica | D9: Celula de Energia | E9: Incomum | F9: Alvo perde Reacao, cibernetica falha 1 rodada.
A10: Bateria de Carro c/ Garras | B10: 3 | C10: Eletrica | D10: Celula de Energia | E10: Incomum | F10: Improvisada, Pesada, Lenta.
A11: Macarico de Solda Portatil | B11: 6 | C11: Incendiaria | D11: Quimica | E11: Incomum | F11: ERA 'combustivel 6 rodadas' - virou Carga (6) na Aprovacao 028.
A12: "Cantor" dardo chamariz | B12: 2 | C12: Chamariz | D12: Pecas Mecanicas | E12: Comum | F12: Unico item de carga barata do catalogo.
A13: Eletrodos (modificacao) | B13: - | C13: Eletrica | D13: Celula de Energia | E13: Incomum | F13: ERA 'Energia da Celula' - o termo foi APOSENTADO. Hoje e Carga.
A15: 2. MUNICAO: a tabela desta aba foi SUBSTITUIDA na Aprovacao 033 - ver a aba Saque.
A17: A tabela de municao da Aprovacao 028 (1d20 POR PERSONAGEM, 2 por cena, so municao) foi trocada pela
A18: TABELA UNICA DE SAQUE DO GRUPO (aba Saque): municao, componentes, armas e equipamento numa rolagem so.
A19: Combates com arma de fogo: antes 31% / 35% / 48% (Rifle/Leve/Cartucho), agora 20% / 22% / 27%.
A21: A PALAVRA 'CARGA' DESCEU DE 4 PARA 3 SENTIDOS: a Energia da Celula foi dissolvida e virou Carga.
A22: Combustivel (Macarico) e bateria (Rebarbadora) tambem viraram Carga: Carga (6) e Carga (4).
A24: UM POOL, DUAS BOCAS: Celula de Energia gasta em arma NAO alimenta o Refugio, e vice-versa.
